Workbook
Name Holidays: Holidays!$A$6:$A$9

Sheet WBS
A1: ⚠ SIMULATED PROJECT: FICTIONAL COMPANY, CREATED FOR PORTFOLIO AND LEARNING PURPOSES · Cobbleway Home Services Ltd is not a real business
A2: Work breakdown structure
A3: Deliverable-based: 8 phases, 30 work packages and milestones.
A5: WBS | B5: Element | C5: Deliverable | D5: Owner | E5: Effort (person-days)
A6: 1 | B6: INITIATION | C6: Approved business case, charter and stakeholder register | D6: Chidera Ikenna-Obi
A7: 1.1 | B7: Business case and options appraisal | D7: Chidera Ikenna-Obi | E7: 4
A8: 1.2 | B8: Project charter | D8: Chidera Ikenna-Obi | E8: 2
A9: 1.3 | B9: Stakeholder analysis and register | D9: Chidera Ikenna-Obi | E9: 1.5
A10: 1.4 | B10: ◆ M1 Charter and business case approved | C10: Milestone | D10: Helen Marsh
A11: 2 | B11: REQUIREMENTS AND SUPPLIER SELECTION | C11: Signed-off MoSCoW requirements; supplier contract | D11: Chidera Ikenna-Obi
A12: 2.1 | B12: Current-process mapping workshops | D12: Chidera Ikenna-Obi | E12: 6
A13: 2.2 | B13: Requirements catalogue (MoSCoW) | D13: Chidera Ikenna-Obi | E13: 4
A14: 2.3 | B14: ◆ M2 Requirements signed off | C14: Milestone | D14: Dave Pearson
A15: 2.4 | B15: Supplier shortlist, demos and scoring | D15: Chidera Ikenna-Obi | E15: 6
A16: 2.5 | B16: ◆ M3 Supplier selected and contract signed | C16: Milestone | D16: Helen Marsh
A17: 3 | B17: DESIGN AND CONFIGURATION | C17: Configured CRM with integrations and mobile app | D17: Sam Carter
A18: 3.1 | B18: Solution design and data model | D18: Sam Carter | E18: 5
A19: 3.2 | B19: Configure enquiries, quotes and pipeline | D19: Sam Carter | E19: 9
A20: 3.3 | B20: Configure jobs, scheduling and service reminders | D20: Sam Carter | E20: 6
A21: 3.4 | B21: Accounting and email integration | D21: Sam Carter | E21: 7
A22: 3.5 | B22: Field mobile app set-up and tablets | D22: Ben Ward | E22: 3
A23: 3.6 | B23: ◆ M4 Configuration complete | C23: Milestone | D23: Sam Carter
A24: 4 | B24: DATA MIGRATION | C24: Cleansed, reconciled customer data | D24: Priya Shah
A25: 4.1 | B25: Data audit and cleansing | D25: Priya Shah | E25: 10
A26: 4.2 | B26: Trial migration and reconciliation | D26: Sam Carter | E26: 3
A27: 5 | B27: TESTING | C27: UAT results and go/no-go decision | D27: Dave Pearson
A28: 5.1 | B28: UAT scripts and test data | D28: Chidera Ikenna-Obi | E28: 2.5
A29: 5.2 | B29: User acceptance testing | D29: Dave Pearson | E29: 8
A30: 5.3 | B30: ◆ M5 Go/no-go decision | C30: Milestone | D30: Helen Marsh
A31: 6 | B31: TRAINING AND CHANGE | C31: Trained users, champions network, guides | D31: Priya Shah
A32: 6.1 | B32: Change impact assessment and champions network | D32: Chidera Ikenna-Obi | E32: 2.5
A33: 6.2 | B33: Training materials and quick-reference guides | D33: Priya Shah | E33: 4
A34: 6.3 | B34: Office team training | D34: Priya Shah | E34: 6
A35: 6.4 | B35: Field engineer training (two sessions) | D35: Gary Hodgson | E35: 8
A36: 7 | B36: DEPLOYMENT | C36: Live CRM and hypercare support | D36: Chidera Ikenna-Obi
A37: 7.1 | B37: Final data migration and cut-over | D37: Sam Carter | E37: 3
A38: 7.2 | B38: ◆ M6 Go-live | C38: Milestone | D38: Helen Marsh
A39: 7.3 | B39: Hypercare support | D39: Priya Shah | E39: 6
A40: 8 | B40: CLOSURE | C40: Lessons learned, closure report, BAU handover | D40: Chidera Ikenna-Obi
A41: 8.1 | B41: Lessons learned workshop | D41: Chidera Ikenna-Obi | E41: 2
...

Sheet Task list
A1: ⚠ SIMULATED PROJECT: FICTIONAL COMPANY, CREATED FOR PORTFOLIO AND LEARNING PURPOSES · Cobbleway Home Services Ltd is not a real business
A2: Task list: durations, dependencies, baseline and actual dates
A3: Durations in working days (Mon to Fri, excluding UK bank holidays). Baseline approved at M1. Actuals final at closure (16 Jun 2026).
A5: ID | B5: WBS | C5: Task | D5: Owner | E5: Effort (pd) | F5: Baseline dur (d) | G5: Baseline start | H5: Baseline finish | I5: Predecessors | J5: Actual start | K5: Actual finish | L5: Actual dur (d) | M5: Finish variance (d) | N5: Milestone
A6: 1 | B6: 1 | C6: Initiation | E6: =SUM(E7:E10) -> 0 | F6: =NETWORKDAYS(G6,H6,Holidays) -> 0 | G6: =MIN(G7:G10) -> 2026-03-02 00:00:00 | H6: =MAX(H7:H10) -> 2026-03-11 00:00:00 | J6: =MIN(J7:J10) -> 2026-03-02 00:00:00 | K6: =MAX(K7:K10) -> 2026-03-11 00:00:00 | L6: =NETWORKDAYS(J6,K6,Holidays) -> 0 | M6: =IF(K6>=H6,NETWORKDAYS(H6,K6,Holidays)-1,-(NETWORKDAYS(K6,H6,Holidays)-1)) -> 0
A7: 2 | B7: 1.1 | C7: Business case and options appraisal | D7: Chidera Ikenna-Obi | E7: 4 | F7: 5 | G7: 46083 | H7: 46087 | J7: 46083 | K7: 46087 | L7: =NETWORKDAYS(J7,K7,Holidays) -> 0 | M7: =IF(K7>=H7,NETWORKDAYS(H7,K7,Holidays)-1,-(NETWORKDAYS(K7,H7,Holidays)-1)) -> 0
A8: 3 | B8: 1.2 | C8: Project charter | D8: Chidera Ikenna-Obi | E8: 2 | F8: 3 | G8: 46090 | H8: 46092 | I8: 2 | J8: 46090 | K8: 46092 | L8: =NETWORKDAYS(J8,K8,Holidays) -> 0 | M8: =IF(K8>=H8,NETWORKDAYS(H8,K8,Holidays)-1,-(NETWORKDAYS(K8,H8,Holidays)-1)) -> 0
A9: 4 | B9: 1.3 | C9: Stakeholder analysis and register | D9: Chidera Ikenna-Obi | E9: 1.5 | F9: 2 | G9: 46090 | H9: 46091 | I9: 2 | J9: 46090 | K9: 46091 | L9: =NETWORKDAYS(J9,K9,Holidays) -> 0 | M9: =IF(K9>=H9,NETWORKDAYS(H9,K9,Holidays)-1,-(NETWORKDAYS(K9,H9,Holidays)-1)) -> 0
A10: 5 | B10: 1.4 | C10: M1 Charter and business case approved | D10: Helen Marsh | E10: 0 | F10: 0 | G10: 46092 | H10: 46092 | I10: 3, 4 | J10: 46092 | K10: 46092 | L10: 0 | M10: =IF(K10>=H10,NETWORKDAYS(H10,K10,Holidays)-1,-(NETWORKDAYS(K10,H10,Holidays)-1)) -> 0 | N10: Yes
A11: 6 | B11: 2 | C11: Requirements and supplier selection | E11: =SUM(E12:E16) -> 0 | F11: =NETWORKDAYS(G11,H11,Holidays) -> 0 | G11: =MIN(G12:G16) -> 2026-03-12 00:00:00 | H11: =MAX(H12:H16) -> 2026-04-07 00:00:00 | J11: =MIN(J12:J16) -> 2026-03-12 00:00:00 | K11: =MAX(K12:K16) -> 2026-04-07 00:00:00 | L11: =NETWORKDAYS(J11,K11,Holidays) -> 0 | M11: =IF(K11>=H11,NETWORKDAYS(H11,K11,Holidays)-1,-(NETWORKDAYS(K11,H11,Holidays)-1)) -> 0
A12: 7 | B12: 2.1 | C12: Current-process mapping workshops | D12: Chidera Ikenna-Obi | E12: 6 | F12: 5 | G12: 46093 | H12: 46099 | I12: 5 | J12: 46093 | K12: 46099 | L12: =NETWORKDAYS(J12,K12,Holidays) -> 0 | M12: =IF(K12>=H12,NETWORKDAYS(H12,K12,Holidays)-1,-(NETWORKDAYS(K12,H12,Holidays)-1)) -> 0
A13: 8 | B13: 2.2 | C13: Requirements catalogue (MoSCoW) | D13: Chidera Ikenna-Obi | E13: 4 | F13: 4 | G13: 46100 | H13: 46105 | I13: 7 | J13: 46100 | K13: 46105 | L13: =NETWORKDAYS(J13,K13,Holidays) -> 0 | M13: =IF(K13>=H13,NETWORKDAYS(H13,K13,Holidays)-1,-(NETWORKDAYS(K13,H13,Holidays)-1)) -> 0
A14: 9 | B14: 2.3 | C14: M2 Requirements signed off | D14: Dave Pearson | E14: 0 | F14: 0 | G14: 46105 | H14: 46105 | I14: 8 | J14: 46105 | K14: 46105 | L14: 0 | M14: =IF(K14>=H14,NETWORKDAYS(H14,K14,Holidays)-1,-(NETWORKDAYS(K14,H14,Holidays)-1)) -> 0 | N14: Yes
A15: 10 | B15: 2.4 | C15: Supplier shortlist, demos and scoring | D15: Chidera Ikenna-Obi | E15: 6 | F15: 8 | G15: 46106 | H15: 46119 | I15: 9 | J15: 46106 | K15: 46119 | L15: =NETWORKDAYS(J15,K15,Holidays) -> 0 | M15: =IF(K15>=H15,NETWORKDAYS(H15,K15,Holidays)-1,-(NETWORKDAYS(K15,H15,Holidays)-1)) -> 0
A16: 11 | B16: 2.5 | C16: M3 Supplier selected and contract signed | D16: Helen Marsh | E16: 0 | F16: 0 | G16: 46119 | H16: 46119 | I16: 10 | J16: 46119 | K16: 46119 | L16: 0 | M16: =IF(K16>=H16,NETWORKDAYS(H16,K16,Holidays)-1,-(NETWORKDAYS(K16,H16,Holidays)-1)) -> 0 | N16: Yes
A17: 12 | B17: 3 | C17: Design and configuration | E17: =SUM(E18:E23) -> 0 | F17: =NETWORKDAYS(G17,H17,Holidays) -> 0 | G17: =MIN(G18:G23) -> 2026-04-08 00:00:00 | H17: =MAX(H18:H23) -> 2026-05-12 00:00:00 | J17: =MIN(J18:J23) -> 2026-04-08 00:00:00 | K17: =MAX(K18:K23) -> 2026-05-12 00:00:00 | L17: =NETWORKDAYS(J17,K17,Holidays) -> 0 | M17: =IF(K17>=H17,NETWORKDAYS(H17,K17,Holidays)-1,-(NETWORKDAYS(K17,H17,Holidays)-1)) -> 0
A18: 13 | B18: 3.1 | C18: Solution design and data model | D18: Sam Carter | E18: 5 | F18: 5 | G18: 46120 | H18: 46126 | I18: 11 | J18: 46120 | K18: 46126 | L18: =NETWORKDAYS(J18,K18,Holidays) -> 0 | M18: =IF(K18>=H18,NETWORKDAYS(H18,K18,Holidays)-1,-(NETWORKDAYS(K18,H18,Holidays)-1)) -> 0
A19: 14 | B19: 3.2 | C19: Configure enquiries, quotes and pipeline | D19: Sam Carter | E19: 9 | F19: 10 | G19: 46127 | H19: 46140 | I19: 13 | J19: 46127 | K19: 46140 | L19: =NETWORKDAYS(J19,K19,Holidays) -> 0 | M19: =IF(K19>=H19,NETWORKDAYS(H19,K19,Holidays)-1,-(NETWORKDAYS(K19,H19,Holidays)-1)) -> 0
A20: 15 | B20: 3.3 | C20: Configure jobs, scheduling and service reminders | D20: Sam Carter | E20: 6 | F20: 6 | G20: 46141 | H20: 46149 | I20: 14 | J20: 46141 | K20: 46149 | L20: =NETWORKDAYS(J20,K20,Holidays) -> 0 | M20: =IF(K20>=H20,NETWORKDAYS(H20,K20,Holidays)-1,-(NETWORKDAYS(K20,H20,Holidays)-1)) -> 0
A21: 16 | B21: 3.4 | C21: Accounting and email integration | D21: Sam Carter | E21: 7 | F21: 6 | G21: 46127 | H21: 46134 | I21: 13 | J21: 46127 | K21: 46139 | L21: =NETWORKDAYS(J21,K21,Holidays) -> 0 | M21: =IF(K21>=H21,NETWORKDAYS(H21,K21,Holidays)-1,-(NETWORKDAYS(K21,H21,Holidays)-1)) -> 0
A22: 17 | B22: 3.5 | C22: Field mobile app set-up and tablets | D22: Ben Ward | E22: 3 | F22: 3 | G22: 46150 | H22: 46154 | I22: 15 | J22: 46150 | K22: 46154 | L22: =NETWORKDAYS(J22,K22,Holidays) -> 0 | M22: =IF(K22>=H22,NETWORKDAYS(H22,K22,Holidays)-1,-(NETWORKDAYS(K22,H22,Holidays)-1)) -> 0
A23: 18 | B23: 3.6 | C23: M4 Configuration complete | D23: Sam Carter | E23: 0 | F23: 0 | G23: 46154 | H23: 46154 | I23: 16, 17 | J23: 46154 | K23: 46154 | L23: 0 | M23: =IF(K23>=H23,NETWORKDAYS(H23,K23,Holidays)-1,-(NETWORKDAYS(K23,H23,Holidays)-1)) -> 0 | N23: Yes
A24: 19 | B24: 4 | C24: Data migration | E24: =SUM(E25:E26) -> 0 | F24: =NETWORKDAYS(G24,H24,Holidays) -> 0 | G24: =MIN(G25:G26) -> 2026-04-15 00:00:00 | H24: =MAX(H25:H26) -> 2026-05-12 00:00:00 | J24: =MIN(J25:J26) -> 2026-04-15 00:00:00 | K24: =MAX(K25:K26) -> 2026-05-18 00:00:00 | L24: =NETWORKDAYS(J24,K24,Holidays) -> 0 | M24: =IF(K24>=H24,NETWORKDAYS(H24,K24,Holidays)-1,-(NETWORKDAYS(K24,H24,Holidays)-1)) -> 0
A25: 20 | B25: 4.1 | C25: Data audit and cleansing | D25: Priya Shah | E25: 10 | F25: 10 | G25: 46127 | H25: 46140 | I25: 13 | J25: 46127 | K25: 46155 | L25: =NETWORKDAYS(J25,K25,Holidays) -> 0 | M25: =IF(K25>=H25,NETWORKDAYS(H25,K25,Holidays)-1,-(NETWORKDAYS(K25,H25,Holidays)-1)) -> 0
A26: 21 | B26: 4.2 | C26: Trial migration and reconciliation | D26: Sam Carter | E26: 3 | F26: 3 | G26: 46150 | H26: 46154 | I26: 20, 15 | J26: 46156 | K26: 46160 | L26: =NETWORKDAYS(J26,K26,Holidays) -> 0 | M26: =IF(K26>=H26,NETWORKDAYS(H26,K26,Holidays)-1,-(NETWORKDAYS(K26,H26,Holidays)-1)) -> 0
A27: 22 | B27: 5 | C27: Testing | E27: =SUM(E28:E30) -> 0 | F27: =NETWORKDAYS(G27,H27,Holidays) -> 0 | G27: =MIN(G28:G30) -> 2026-04-15 00:00:00 | H27: =MAX(H28:H30) -> 2026-05-18 00:00:00 | J27: =MIN(J28:J30) -> 2026-04-15 00:00:00 | K27: =MAX(K28:K30) -> 2026-05-22 00:00:00 | L27: =NETWORKDAYS(J27,K27,Holidays) -> 0 | M27: =IF(K27>=H27,NETWORKDAYS(H27,K27,Holidays)-1,-(NETWORKDAYS(K27,H27,Holidays)-1)) -> 0
A28: 23 | B28: 5.1 | C28: UAT scripts and test data | D28: Chidera Ikenna-Obi | E28: 2.5 | F28: 3 | G28: 46127 | H28: 46129 | I28: 13 | J28: 46127 | K28: 46129 | L28: =NETWORKDAYS(J28,K28,Holidays) -> 0 | M28: =IF(K28>=H28,NETWORKDAYS(H28,K28,Holidays)-1,-(NETWORKDAYS(K28,H28,Holidays)-1)) -> 0
A29: 24 | B29: 5.2 | C29: User acceptance testing | D29: Dave Pearson | E29: 8 | F29: 4 | G29: 46155 | H29: 46160 | I29: 18, 21, 23 | J29: 46161 | K29: 46164 | L29: =NETWORKDAYS(J29,K29,Holidays) -> 0 | M29: =IF(K29>=H29,NETWORKDAYS(H29,K29,Holidays)-1,-(NETWORKDAYS(K29,H29,Holidays)-1)) -> 0
A30: 25 | B30: 5.3 | C30: M5 Go/no-go decision | D30: Helen Marsh | E30: 0 | F30: 0 | G30: 46160 | H30: 46160 | I30: 24, 29, 30 | J30: 46164 | K30: 46164 | L30: 0 | M30: =IF(K30>=H30,NETWORKDAYS(H30,K30,Holidays)-1,-(NETWORKDAYS(K30,H30,Holidays)-1)) -> 0 | N30: Yes
A31: 26 | B31: 6 | C31: Training and change | E31: =SUM(E32:E35) -> 0 | F31: =NETWORKDAYS(G31,H31,Holidays) -> 0 | G31: =MIN(G32:G35) -> 2026-03-25 00:00:00 | H31: =MAX(H32:H35) -> 2026-05-15 00:00:00 | J31: =MIN(J32:J35) -> 2026-03-25 00:00:00 | K31: =MAX(K32:K35) -> 2026-05-15 00:00:00 | L31: =NETWORKDAYS(J31,K31,Holidays) -> 0 | M31: =IF(K31>=H31,NETWORKDAYS(H31,K31,Holidays)-1,-(NETWORKDAYS(K31,H31,Holidays)-1)) -> 0
A32: 27 | B32: 6.1 | C32: Change impact assessment and champions network | D32: Chidera Ikenna-Obi | E32: 2.5 | F32: 3 | G32: 46106 | H32: 46108 | I32: 9 | J32: 46106 | K32: 46108 | L32: =NETWORKDAYS(J32,K32,Holidays) -> 0 | M32: =IF(K32>=H32,NETWORKDAYS(H32,K32,Holidays)-1,-(NETWORKDAYS(K32,H32,Holidays)-1)) -> 0
A33: 28 | B33: 6.2 | C33: Training materials and quick-reference guides | D33: Priya Shah | E33: 4 | F33: 4 | G33: 46150 | H33: 46155 | I33: 15 | J33: 46150 | K33: 46155 | L33: =NETWORKDAYS(J33,K33,Holidays) -> 0 | M33: =IF(K33>=H33,NETWORKDAYS(H33,K33,Holidays)-1,-(NETWORKDAYS(K33,H33,Holidays)-1)) -> 0
A34: 29 | B34: 6.3 | C34: Office team training | D34: Priya Shah | E34: 6 | F34: 2 | G34: 46156 | H34: 46157 | I34: 28 | J34: 46156 | K34: 46157 | L34: =NETWORKDAYS(J34,K34,Holidays) -> 0 | M34: =IF(K34>=H34,NETWORKDAYS(H34,K34,Holidays)-1,-(NETWORKDAYS(K34,H34,Holidays)-1)) -> 0
A35: 30 | B35: 6.4 | C35: Field engineer training (two sessions) | D35: Gary Hodgson | E35: 8 | F35: 2 | G35: 46156 | H35: 46157 | I35: 28 | J35: 46156 | K35: 46157 | L35: =NETWORKDAYS(J35,K35,Holidays) -> 0 | M35: =IF(K35>=H35,NETWORKDAYS(H35,K35,Holidays)-1,-(NETWORKDAYS(K35,H35,Holidays)-1)) -> 0
A36: 31 | B36: 7 | C36: Deployment | E36: =SUM(E37:E39) -> 0 | F36: =NETWORKDAYS(G36,H36,Holidays) -> 0 | G36: =MIN(G37:G39) -> 2026-05-19 00:00:00 | H36: =MAX(H37:H39) -> 2026-06-04 00:00:00 | J36: =MIN(J37:J39) -> 2026-05-26 00:00:00 | K36: =MAX(K37:K39) -> 2026-06-10 00:00:00 | L36: =NETWORKDAYS(J36,K36,Holidays) -> 0 | M36: =IF(K36>=H36,NETWORKDAYS(H36,K36,Holidays)-1,-(NETWORKDAYS(K36,H36,Holidays)-1)) -> 0
A37: 32 | B37: 7.1 | C37: Final data migration and cut-over | D37: Sam Carter | E37: 3 | F37: 2 | G37: 46161 | H37: 46162 | I37: 25 | J37: 46168 | K37: 46169 | L37: =NETWORKDAYS(J37,K37,Holidays) -> 0 | M37: =IF(K37>=H37,NETWORKDAYS(H37,K37,Holidays)-1,-(NETWORKDAYS(K37,H37,Holidays)-1)) -> 0
A38: 33 | B38: 7.2 | C38: M6 Go-live | D38: Helen Marsh | E38: 0 | F38: 0 | G38: 46162 | H38: 46162 | I38: 32 | J38: 46169 | K38: 46169 | L38: 0 | M38: =IF(K38>=H38,NETWORKDAYS(H38,K38,Holidays)-1,-(NETWORKDAYS(K38,H38,Holidays)-1)) -> 0 | N38: Yes
A39: 34 | B39: 7.3 | C39: Hypercare support | D39: Priya Shah | E39: 6 | F39: 10 | G39: 46163 | H39: 46177 | I39: 33 | J39: 46170 | K39: 46183 | L39: =NETWORKDAYS(J39,K39,Holidays) -> 0 | M39: =IF(K39>=H39,NETWORKDAYS(H39,K39,Holidays)-1,-(NETWORKDAYS(K39,H39,Holidays)-1)) -> 0
A40: 35 | B40: 8 | C40: Closure | E40: =SUM(E41:E43) -> 0 | F40: =NETWORKDAYS(G40,H40,Holidays) -> 0 | G40: =MIN(G41:G43) -> 2026-06-05 00:00:00 | H40: =MAX(H41:H43) -> 2026-06-10 00:00:00 | J40: =MIN(J41:J43) -> 2026-06-11 00:00:00 | K40: =MAX(K41:K43) -> 2026-06-16 00:00:00 | L40: =NETWORKDAYS(J40,K40,Holidays) -> 0 | M40: =IF(K40>=H40,NETWORKDAYS(H40,K40,Holidays)-1,-(NETWORKDAYS(K40,H40,Holidays)-1)) -> 0
A41: 36 | B41: 8.1 | C41: Lessons learned workshop | D41: Chidera Ikenna-Obi | E41: 2 | F41: 1 | G41: 46178 | H41: 46178 | I41: 34 | J41: 46184 | K41: 46184 | L41: =NETWORKDAYS(J41,K41,Holidays) -> 0 | M41: =IF(K41>=H41,NETWORKDAYS(H41,K41,Holidays)-1,-(NETWORKDAYS(K41,H41,Holidays)-1)) -> 0
...

Sheet Gantt
A1: ⚠ SIMULATED PROJECT: FICTIONAL COMPANY, CREATED FOR PORTFOLIO AND LEARNING PURPOSES · Cobbleway Home Services Ltd is not a real business
A2: Gantt view (weekly)
A3: Teal = actual; grey = baseline not achieved (shows slip); ◆ = milestone (actual); ◇ = baseline milestone. Driven by formulas from the Task list.
A5: ID | B5: WBS | C5: Task | D5: Actual start | E5: Actual finish | F5: Var | G5: 46083 | H5: 46090 | I5: 46097 | J5: 46104 | K5: 46111 | L5: 46118 | M5: 46125 | N5: 46132 | O5: 46139 | P5: 46146 | Q5: 46153 | R5: 46160 | S5: 46167 | T5: 46174 | U5: 46181 | V5: 46188
A6: ='Task list'!A6 -> 1 | B6: ='Task list'!B6 -> 1 | C6: ='Task list'!C6 -> Initiation | D6: ='Task list'!J6 -> 2026-03-02 00:00:00 | E6: ='Task list'!K6 -> 2026-03-11 00:00:00 | F6: ='Task list'!M6 -> 0 | W6: ='Task list'!G6 -> 2026-03-02 00:00:00 | X6: ='Task list'!H6 -> 2026-03-11 00:00:00 | Y6: ='Task list'!N6
A7: ='Task list'!A7 -> 2 | B7: ='Task list'!B7 -> 1.1 | C7: ='Task list'!C7 -> Business case and options appraisal | D7: ='Task list'!J7 -> 2026-03-02 00:00:00 | E7: ='Task list'!K7 -> 2026-03-06 00:00:00 | F7: ='Task list'!M7 -> 0 | W7: ='Task list'!G7 -> 2026-03-02 00:00:00 | X7: ='Task list'!H7 -> 2026-03-06 00:00:00 | Y7: ='Task list'!N7
A8: ='Task list'!A8 -> 3 | B8: ='Task list'!B8 -> 1.2 | C8: ='Task list'!C8 -> Project charter | D8: ='Task list'!J8 -> 2026-03-09 00:00:00 | E8: ='Task list'!K8 -> 2026-03-11 00:00:00 | F8: ='Task list'!M8 -> 0 | W8: ='Task list'!G8 -> 2026-03-09 00:00:00 | X8: ='Task list'!H8 -> 2026-03-11 00:00:00 | Y8: ='Task list'!N8
A9: ='Task list'!A9 -> 4 | B9: ='Task list'!B9 -> 1.3 | C9: ='Task list'!C9 -> Stakeholder analysis and register | D9: ='Task list'!J9 -> 2026-03-09 00:00:00 | E9: ='Task list'!K9 -> 2026-03-10 00:00:00 | F9: ='Task list'!M9 -> 0 | W9: ='Task list'!G9 -> 2026-03-09 00:00:00 | X9: ='Task list'!H9 -> 2026-03-10 00:00:00 | Y9: ='Task list'!N9
A10: ='Task list'!A10 -> 5 | B10: ='Task list'!B10 -> 1.4 | C10: ='Task list'!C10 -> M1 Charter and business case approved | D10: ='Task list'!J10 -> 2026-03-11 00:00:00 | E10: ='Task list'!K10 -> 2026-03-11 00:00:00 | F10: ='Task list'!M10 -> 0 | G10: =IF(AND('Task list'!$K10>=G$5,'Task list'!$K10<G$5+7),"◆",IF(AND('Task list'!$H10>=G$5,'Task list'!$H10<G$5+7),"◇","")) -> 0 | H10: =IF(AND('Task list'!$K10>=H$5,'Task list'!$K10<H$5+7),"◆",IF(AND('Task list'!$H10>=H$5,'Task list'!$H10<H$5+7),"◇","")) -> 0 | I10: =IF(AND('Task list'!$K10>=I$5,'Task list'!$K10<I$5+7),"◆",IF(AND('Task list'!$H10>=I$5,'Task list'!$H10<I$5+7),"◇","")) -> 0 | J10: =IF(AND('Task list'!$K10>=J$5,'Task list'!$K10<J$5+7),"◆",IF(AND('Task list'!$H10>=J$5,'Task list'!$H10<J$5+7),"◇","")) -> 0 | K10: =IF(AND('Task list'!$K10>=K$5,'Task list'!$K10<K$5+7),"◆",IF(AND('Task list'!$H10>=K$5,'Task list'!$H10<K$5+7),"◇","")) -> 0 | L10: =IF(AND('Task list'!$K10>=L$5,'Task list'!$K10<L$5+7),"◆",IF(AND('Task list'!$H10>=L$5,'Task list'!$H10<L$5+7),"◇","")) -> 0 | M10: =IF(AND('Task list'!$K10>=M$5,'Task list'!$K10<M$5+7),"◆",IF(AND('Task list'!$H10>=M$5,'Task list'!$H10<M$5+7),"◇","")) -> 0 | N10: =IF(AND('Task list'!$K10>=N$5,'Task list'!$K10<N$5+7),"◆",IF(AND('Task list'!$H10>=N$5,'Task list'!$H10<N$5+7),"◇","")) -> 0 | ... V10: =IF(AND('Task list'!$K10>=V$5,'Task list'!$K10<V$5+7),"◆",IF(AND('Task list'!$H10>=V$5,'Task list'!$H10<V$5+7),"◇","")) -> 0 | W10: ='Task list'!G10 -> 2026-03-11 00:00:00 | X10: ='Task list'!H10 -> 2026-03-11 00:00:00 | Y10: ='Task list'!N10 -> Yes
A11: ='Task list'!A11 -> 6 | B11: ='Task list'!B11 -> 2 | C11: ='Task list'!C11 -> Requirements and supplier selection | D11: ='Task list'!J11 -> 2026-03-12 00:00:00 | E11: ='Task list'!K11 -> 2026-04-07 00:00:00 | F11: ='Task list'!M11 -> 0 | W11: ='Task list'!G11 -> 2026-03-12 00:00:00 | X11: ='Task list'!H11 -> 2026-04-07 00:00:00 | Y11: ='Task list'!N11
A12: ='Task list'!A12 -> 7 | B12: ='Task list'!B12 -> 2.1 | C12: ='Task list'!C12 -> Current-process mapping workshops | D12: ='Task list'!J12 -> 2026-03-12 00:00:00 | E12: ='Task list'!K12 -> 2026-03-18 00:00:00 | F12: ='Task list'!M12 -> 0 | W12: ='Task list'!G12 -> 2026-03-12 00:00:00 | X12: ='Task list'!H12 -> 2026-03-18 00:00:00 | Y12: ='Task list'!N12
A13: ='Task list'!A13 -> 8 | B13: ='Task list'!B13 -> 2.2 | C13: ='Task list'!C13 -> Requirements catalogue (MoSCoW) | D13: ='Task list'!J13 -> 2026-03-19 00:00:00 | E13: ='Task list'!K13 -> 2026-03-24 00:00:00 | F13: ='Task list'!M13 -> 0 | W13: ='Task list'!G13 -> 2026-03-19 00:00:00 | X13: ='Task list'!H13 -> 2026-03-24 00:00:00 | Y13: ='Task list'!N13
A14: ='Task list'!A14 -> 9 | B14: ='Task list'!B14 -> 2.3 | C14: ='Task list'!C14 -> M2 Requirements signed off | D14: ='Task list'!J14 -> 2026-03-24 00:00:00 | E14: ='Task list'!K14 -> 2026-03-24 00:00:00 | F14: ='Task list'!M14 -> 0 | G14: =IF(AND('Task list'!$K14>=G$5,'Task list'!$K14<G$5+7),"◆",IF(AND('Task list'!$H14>=G$5,'Task list'!$H14<G$5+7),"◇","")) -> 0 | H14: =IF(AND('Task list'!$K14>=H$5,'Task list'!$K14<H$5+7),"◆",IF(AND('Task list'!$H14>=H$5,'Task list'!$H14<H$5+7),"◇","")) -> 0 | I14: =IF(AND('Task list'!$K14>=I$5,'Task list'!$K14<I$5+7),"◆",IF(AND('Task list'!$H14>=I$5,'Task list'!$H14<I$5+7),"◇","")) -> 0 | J14: =IF(AND('Task list'!$K14>=J$5,'Task list'!$K14<J$5+7),"◆",IF(AND('Task list'!$H14>=J$5,'Task list'!$H14<J$5+7),"◇","")) -> 0 | K14: =IF(AND('Task list'!$K14>=K$5,'Task list'!$K14<K$5+7),"◆",IF(AND('Task list'!$H14>=K$5,'Task list'!$H14<K$5+7),"◇","")) -> 0 | L14: =IF(AND('Task list'!$K14>=L$5,'Task list'!$K14<L$5+7),"◆",IF(AND('Task list'!$H14>=L$5,'Task list'!$H14<L$5+7),"◇","")) -> 0 | M14: =IF(AND('Task list'!$K14>=M$5,'Task list'!$K14<M$5+7),"◆",IF(AND('Task list'!$H14>=M$5,'Task list'!$H14<M$5+7),"◇","")) -> 0 | N14: =IF(AND('Task list'!$K14>=N$5,'Task list'!$K14<N$5+7),"◆",IF(AND('Task list'!$H14>=N$5,'Task list'!$H14<N$5+7),"◇","")) -> 0 | ... V14: =IF(AND('Task list'!$K14>=V$5,'Task list'!$K14<V$5+7),"◆",IF(AND('Task list'!$H14>=V$5,'Task list'!$H14<V$5+7),"◇","")) -> 0 | W14: ='Task list'!G14 -> 2026-03-24 00:00:00 | X14: ='Task list'!H14 -> 2026-03-24 00:00:00 | Y14: ='Task list'!N14 -> Yes
A15: ='Task list'!A15 -> 10 | B15: ='Task list'!B15 -> 2.4 | C15: ='Task list'!C15 -> Supplier shortlist, demos and scoring | D15: ='Task list'!J15 -> 2026-03-25 00:00:00 | E15: ='Task list'!K15 -> 2026-04-07 00:00:00 | F15: ='Task list'!M15 -> 0 | W15: ='Task list'!G15 -> 2026-03-25 00:00:00 | X15: ='Task list'!H15 -> 2026-04-07 00:00:00 | Y15: ='Task list'!N15
A16: ='Task list'!A16 -> 11 | B16: ='Task list'!B16 -> 2.5 | C16: ='Task list'!C16 -> M3 Supplier selected and contract signed | D16: ='Task list'!J16 -> 2026-04-07 00:00:00 | E16: ='Task list'!K16 -> 2026-04-07 00:00:00 | F16: ='Task list'!M16 -> 0 | G16: =IF(AND('Task list'!$K16>=G$5,'Task list'!$K16<G$5+7),"◆",IF(AND('Task list'!$H16>=G$5,'Task list'!$H16<G$5+7),"◇","")) -> 0 | H16: =IF(AND('Task list'!$K16>=H$5,'Task list'!$K16<H$5+7),"◆",IF(AND('Task list'!$H16>=H$5,'Task list'!$H16<H$5+7),"◇","")) -> 0 | I16: =IF(AND('Task list'!$K16>=I$5,'Task list'!$K16<I$5+7),"◆",IF(AND('Task list'!$H16>=I$5,'Task list'!$H16<I$5+7),"◇","")) -> 0 | J16: =IF(AND('Task list'!$K16>=J$5,'Task list'!$K16<J$5+7),"◆",IF(AND('Task list'!$H16>=J$5,'Task list'!$H16<J$5+7),"◇","")) -> 0 | K16: =IF(AND('Task list'!$K16>=K$5,'Task list'!$K16<K$5+7),"◆",IF(AND('Task list'!$H16>=K$5,'Task list'!$H16<K$5+7),"◇","")) -> 0 | L16: =IF(AND('Task list'!$K16>=L$5,'Task list'!$K16<L$5+7),"◆",IF(AND('Task list'!$H16>=L$5,'Task list'!$H16<L$5+7),"◇","")) -> 0 | M16: =IF(AND('Task list'!$K16>=M$5,'Task list'!$K16<M$5+7),"◆",IF(AND('Task list'!$H16>=M$5,'Task list'!$H16<M$5+7),"◇","")) -> 0 | N16: =IF(AND('Task list'!$K16>=N$5,'Task list'!$K16<N$5+7),"◆",IF(AND('Task list'!$H16>=N$5,'Task list'!$H16<N$5+7),"◇","")) -> 0 | ... V16: =IF(AND('Task list'!$K16>=V$5,'Task list'!$K16<V$5+7),"◆",IF(AND('Task list'!$H16>=V$5,'Task list'!$H16<V$5+7),"◇","")) -> 0 | W16: ='Task list'!G16 -> 2026-04-07 00:00:00 | X16: ='Task list'!H16 -> 2026-04-07 00:00:00 | Y16: ='Task list'!N16 -> Yes
A17: ='Task list'!A17 -> 12 | B17: ='Task list'!B17 -> 3 | C17: ='Task list'!C17 -> Design and configuration | D17: ='Task list'!J17 -> 2026-04-08 00:00:00 | E17: ='Task list'!K17 -> 2026-05-12 00:00:00 | F17: ='Task list'!M17 -> 0 | W17: ='Task list'!G17 -> 2026-04-08 00:00:00 | X17: ='Task list'!H17 -> 2026-05-12 00:00:00 | Y17: ='Task list'!N17
A18: ='Task list'!A18 -> 13 | B18: ='Task list'!B18 -> 3.1 | C18: ='Task list'!C18 -> Solution design and data model | D18: ='Task list'!J18 -> 2026-04-08 00:00:00 | E18: ='Task list'!K18 -> 2026-04-14 00:00:00 | F18: ='Task list'!M18 -> 0 | W18: ='Task list'!G18 -> 2026-04-08 00:00:00 | X18: ='Task list'!H18 -> 2026-04-14 00:00:00 | Y18: ='Task list'!N18
A19: ='Task list'!A19 -> 14 | B19: ='Task list'!B19 -> 3.2 | C19: ='Task list'!C19 -> Configure enquiries, quotes and pipeline | D19: ='Task list'!J19 -> 2026-04-15 00:00:00 | E19: ='Task list'!K19 -> 2026-04-28 00:00:00 | F19: ='Task list'!M19 -> 0 | W19: ='Task list'!G19 -> 2026-04-15 00:00:00 | X19: ='Task list'!H19 -> 2026-04-28 00:00:00 | Y19: ='Task list'!N19
A20: ='Task list'!A20 -> 15 | B20: ='Task list'!B20 -> 3.3 | C20: ='Task list'!C20 -> Configure jobs, scheduling and service reminders | D20: ='Task list'!J20 -> 2026-04-29 00:00:00 | E20: ='Task list'!K20 -> 2026-05-07 00:00:00 | F20: ='Task list'!M20 -> 0 | W20: ='Task list'!G20 -> 2026-04-29 00:00:00 | X20: ='Task list'!H20 -> 2026-05-07 00:00:00 | Y20: ='Task list'!N20
A21: ='Task list'!A21 -> 16 | B21: ='Task list'!B21 -> 3.4 | C21: ='Task list'!C21 -> Accounting and email integration | D21: ='Task list'!J21 -> 2026-04-15 00:00:00 | E21: ='Task list'!K21 -> 2026-04-27 00:00:00 | F21: ='Task list'!M21 -> 0 | W21: ='Task list'!G21 -> 2026-04-15 00:00:00 | X21: ='Task list'!H21 -> 2026-04-22 00:00:00 | Y21: ='Task list'!N21
A22: ='Task list'!A22 -> 17 | B22: ='Task list'!B22 -> 3.5 | C22: ='Task list'!C22 -> Field mobile app set-up and tablets | D22: ='Task list'!J22 -> 2026-05-08 00:00:00 | E22: ='Task list'!K22 -> 2026-05-12 00:00:00 | F22: ='Task list'!M22 -> 0 | W22: ='Task list'!G22 -> 2026-05-08 00:00:00 | X22: ='Task list'!H22 -> 2026-05-12 00:00:00 | Y22: ='Task list'!N22
A23: ='Task list'!A23 -> 18 | B23: ='Task list'!B23 -> 3.6 | C23: ='Task list'!C23 -> M4 Configuration complete | D23: ='Task list'!J23 -> 2026-05-12 00:00:00 | E23: ='Task list'!K23 -> 2026-05-12 00:00:00 | F23: ='Task list'!M23 -> 0 | G23: =IF(AND('Task list'!$K23>=G$5,'Task list'!$K23<G$5+7),"◆",IF(AND('Task list'!$H23>=G$5,'Task list'!$H23<G$5+7),"◇","")) -> 0 | H23: =IF(AND('Task list'!$K23>=H$5,'Task list'!$K23<H$5+7),"◆",IF(AND('Task list'!$H23>=H$5,'Task list'!$H23<H$5+7),"◇","")) -> 0 | I23: =IF(AND('Task list'!$K23>=I$5,'Task list'!$K23<I$5+7),"◆",IF(AND('Task list'!$H23>=I$5,'Task list'!$H23<I$5+7),"◇","")) -> 0 | J23: =IF(AND('Task list'!$K23>=J$5,'Task list'!$K23<J$5+7),"◆",IF(AND('Task list'!$H23>=J$5,'Task list'!$H23<J$5+7),"◇","")) -> 0 | K23: =IF(AND('Task list'!$K23>=K$5,'Task list'!$K23<K$5+7),"◆",IF(AND('Task list'!$H23>=K$5,'Task list'!$H23<K$5+7),"◇","")) -> 0 | L23: =IF(AND('Task list'!$K23>=L$5,'Task list'!$K23<L$5+7),"◆",IF(AND('Task list'!$H23>=L$5,'Task list'!$H23<L$5+7),"◇","")) -> 0 | M23: =IF(AND('Task list'!$K23>=M$5,'Task list'!$K23<M$5+7),"◆",IF(AND('Task list'!$H23>=M$5,'Task list'!$H23<M$5+7),"◇","")) -> 0 | N23: =IF(AND('Task list'!$K23>=N$5,'Task list'!$K23<N$5+7),"◆",IF(AND('Task list'!$H23>=N$5,'Task list'!$H23<N$5+7),"◇","")) -> 0 | ... V23: =IF(AND('Task list'!$K23>=V$5,'Task list'!$K23<V$5+7),"◆",IF(AND('Task list'!$H23>=V$5,'Task list'!$H23<V$5+7),"◇","")) -> 0 | W23: ='Task list'!G23 -> 2026-05-12 00:00:00 | X23: ='Task list'!H23 -> 2026-05-12 00:00:00 | Y23: ='Task list'!N23 -> Yes
A24: ='Task list'!A24 -> 19 | B24: ='Task list'!B24 -> 4 | C24: ='Task list'!C24 -> Data migration | D24: ='Task list'!J24 -> 2026-04-15 00:00:00 | E24: ='Task list'!K24 -> 2026-05-18 00:00:00 | F24: ='Task list'!M24 -> 0 | W24: ='Task list'!G24 -> 2026-04-15 00:00:00 | X24: ='Task list'!H24 -> 2026-05-12 00:00:00 | Y24: ='Task list'!N24
A25: ='Task list'!A25 -> 20 | B25: ='Task list'!B25 -> 4.1 | C25: ='Task list'!C25 -> Data audit and cleansing | D25: ='Task list'!J25 -> 2026-04-15 00:00:00 | E25: ='Task list'!K25 -> 2026-05-13 00:00:00 | F25: ='Task list'!M25 -> 0 | W25: ='Task list'!G25 -> 2026-04-15 00:00:00 | X25: ='Task list'!H25 -> 2026-04-28 00:00:00 | Y25: ='Task list'!N25
A26: ='Task list'!A26 -> 21 | B26: ='Task list'!B26 -> 4.2 | C26: ='Task list'!C26 -> Trial migration and reconciliation | D26: ='Task list'!J26 -> 2026-05-14 00:00:00 | E26: ='Task list'!K26 -> 2026-05-18 00:00:00 | F26: ='Task list'!M26 -> 0 | W26: ='Task list'!G26 -> 2026-05-08 00:00:00 | X26: ='Task list'!H26 -> 2026-05-12 00:00:00 | Y26: ='Task list'!N26
A27: ='Task list'!A27 -> 22 | B27: ='Task list'!B27 -> 5 | C27: ='Task list'!C27 -> Testing | D27: ='Task list'!J27 -> 2026-04-15 00:00:00 | E27: ='Task list'!K27 -> 2026-05-22 00:00:00 | F27: ='Task list'!M27 -> 0 | W27: ='Task list'!G27 -> 2026-04-15 00:00:00 | X27: ='Task list'!H27 -> 2026-05-18 00:00:00 | Y27: ='Task list'!N27
A28: ='Task list'!A28 -> 23 | B28: ='Task list'!B28 -> 5.1 | C28: ='Task list'!C28 -> UAT scripts and test data | D28: ='Task list'!J28 -> 2026-04-15 00:00:00 | E28: ='Task list'!K28 -> 2026-04-17 00:00:00 | F28: ='Task list'!M28 -> 0 | W28: ='Task list'!G28 -> 2026-04-15 00:00:00 | X28: ='Task list'!H28 -> 2026-04-17 00:00:00 | Y28: ='Task list'!N28
A29: ='Task list'!A29 -> 24 | B29: ='Task list'!B29 -> 5.2 | C29: ='Task list'!C29 -> User acceptance testing | D29: ='Task list'!J29 -> 2026-05-19 00:00:00 | E29: ='Task list'!K29 -> 2026-05-22 00:00:00 | F29: ='Task list'!M29 -> 0 | W29: ='Task list'!G29 -> 2026-05-13 00:00:00 | X29: ='Task list'!H29 -> 2026-05-18 00:00:00 | Y29: ='Task list'!N29
A30: ='Task list'!A30 -> 25 | B30: ='Task list'!B30 -> 5.3 | C30: ='Task list'!C30 -> M5 Go/no-go decision | D30: ='Task list'!J30 -> 2026-05-22 00:00:00 | E30: ='Task list'!K30 -> 2026-05-22 00:00:00 | F30: ='Task list'!M30 -> 0 | G30: =IF(AND('Task list'!$K30>=G$5,'Task list'!$K30<G$5+7),"◆",IF(AND('Task list'!$H30>=G$5,'Task list'!$H30<G$5+7),"◇","")) -> 0 | H30: =IF(AND('Task list'!$K30>=H$5,'Task list'!$K30<H$5+7),"◆",IF(AND('Task list'!$H30>=H$5,'Task list'!$H30<H$5+7),"◇","")) -> 0 | I30: =IF(AND('Task list'!$K30>=I$5,'Task list'!$K30<I$5+7),"◆",IF(AND('Task list'!$H30>=I$5,'Task list'!$H30<I$5+7),"◇","")) -> 0 | J30: =IF(AND('Task list'!$K30>=J$5,'Task list'!$K30<J$5+7),"◆",IF(AND('Task list'!$H30>=J$5,'Task list'!$H30<J$5+7),"◇","")) -> 0 | K30: =IF(AND('Task list'!$K30>=K$5,'Task list'!$K30<K$5+7),"◆",IF(AND('Task list'!$H30>=K$5,'Task list'!$H30<K$5+7),"◇","")) -> 0 | L30: =IF(AND('Task list'!$K30>=L$5,'Task list'!$K30<L$5+7),"◆",IF(AND('Task list'!$H30>=L$5,'Task list'!$H30<L$5+7),"◇","")) -> 0 | M30: =IF(AND('Task list'!$K30>=M$5,'Task list'!$K30<M$5+7),"◆",IF(AND('Task list'!$H30>=M$5,'Task list'!$H30<M$5+7),"◇","")) -> 0 | N30: =IF(AND('Task list'!$K30>=N$5,'Task list'!$K30<N$5+7),"◆",IF(AND('Task list'!$H30>=N$5,'Task list'!$H30<N$5+7),"◇","")) -> 0 | ... V30: =IF(AND('Task list'!$K30>=V$5,'Task list'!$K30<V$5+7),"◆",IF(AND('Task list'!$H30>=V$5,'Task list'!$H30<V$5+7),"◇","")) -> 0 | W30: ='Task list'!G30 -> 2026-05-18 00:00:00 | X30: ='Task list'!H30 -> 2026-05-18 00:00:00 | Y30: ='Task list'!N30 -> Yes
A31: ='Task list'!A31 -> 26 | B31: ='Task list'!B31 -> 6 | C31: ='Task list'!C31 -> Training and change | D31: ='Task list'!J31 -> 2026-03-25 00:00:00 | E31: ='Task list'!K31 -> 2026-05-15 00:00:00 | F31: ='Task list'!M31 -> 0 | W31: ='Task list'!G31 -> 2026-03-25 00:00:00 | X31: ='Task list'!H31 -> 2026-05-15 00:00:00 | Y31: ='Task list'!N31
A32: ='Task list'!A32 -> 27 | B32: ='Task list'!B32 -> 6.1 | C32: ='Task list'!C32 -> Change impact assessment and champions network | D32: ='Task list'!J32 -> 2026-03-25 00:00:00 | E32: ='Task list'!K32 -> 2026-03-27 00:00:00 | F32: ='Task list'!M32 -> 0 | W32: ='Task list'!G32 -> 2026-03-25 00:00:00 | X32: ='Task list'!H32 -> 2026-03-27 00:00:00 | Y32: ='Task list'!N32
A33: ='Task list'!A33 -> 28 | B33: ='Task list'!B33 -> 6.2 | C33: ='Task list'!C33 -> Training materials and quick-reference guides | D33: ='Task list'!J33 -> 2026-05-08 00:00:00 | E33: ='Task list'!K33 -> 2026-05-13 00:00:00 | F33: ='Task list'!M33 -> 0 | W33: ='Task list'!G33 -> 2026-05-08 00:00:00 | X33: ='Task list'!H33 -> 2026-05-13 00:00:00 | Y33: ='Task list'!N33
A34: ='Task list'!A34 -> 29 | B34: ='Task list'!B34 -> 6.3 | C34: ='Task list'!C34 -> Office team training | D34: ='Task list'!J34 -> 2026-05-14 00:00:00 | E34: ='Task list'!K34 -> 2026-05-15 00:00:00 | F34: ='Task list'!M34 -> 0 | W34: ='Task list'!G34 -> 2026-05-14 00:00:00 | X34: ='Task list'!H34 -> 2026-05-15 00:00:00 | Y34: ='Task list'!N34
A35: ='Task list'!A35 -> 30 | B35: ='Task list'!B35 -> 6.4 | C35: ='Task list'!C35 -> Field engineer training (two sessions) | D35: ='Task list'!J35 -> 2026-05-14 00:00:00 | E35: ='Task list'!K35 -> 2026-05-15 00:00:00 | F35: ='Task list'!M35 -> 0 | W35: ='Task list'!G35 -> 2026-05-14 00:00:00 | X35: ='Task list'!H35 -> 2026-05-15 00:00:00 | Y35: ='Task list'!N35
A36: ='Task list'!A36 -> 31 | B36: ='Task list'!B36 -> 7 | C36: ='Task list'!C36 -> Deployment | D36: ='Task list'!J36 -> 2026-05-26 00:00:00 | E36: ='Task list'!K36 -> 2026-06-10 00:00:00 | F36: ='Task list'!M36 -> 0 | W36: ='Task list'!G36 -> 2026-05-19 00:00:00 | X36: ='Task list'!H36 -> 2026-06-04 00:00:00 | Y36: ='Task list'!N36
A37: ='Task list'!A37 -> 32 | B37: ='Task list'!B37 -> 7.1 | C37: ='Task list'!C37 -> Final data migration and cut-over | D37: ='Task list'!J37 -> 2026-05-26 00:00:00 | E37: ='Task list'!K37 -> 2026-05-27 00:00:00 | F37: ='Task list'!M37 -> 0 | W37: ='Task list'!G37 -> 2026-05-19 00:00:00 | X37: ='Task list'!H37 -> 2026-05-20 00:00:00 | Y37: ='Task list'!N37
A38: ='Task list'!A38 -> 33 | B38: ='Task list'!B38 -> 7.2 | C38: ='Task list'!C38 -> M6 Go-live | D38: ='Task list'!J38 -> 2026-05-27 00:00:00 | E38: ='Task list'!K38 -> 2026-05-27 00:00:00 | F38: ='Task list'!M38 -> 0 | G38: =IF(AND('Task list'!$K38>=G$5,'Task list'!$K38<G$5+7),"◆",IF(AND('Task list'!$H38>=G$5,'Task list'!$H38<G$5+7),"◇","")) -> 0 | H38: =IF(AND('Task list'!$K38>=H$5,'Task list'!$K38<H$5+7),"◆",IF(AND('Task list'!$H38>=H$5,'Task list'!$H38<H$5+7),"◇","")) -> 0 | I38: =IF(AND('Task list'!$K38>=I$5,'Task list'!$K38<I$5+7),"◆",IF(AND('Task list'!$H38>=I$5,'Task list'!$H38<I$5+7),"◇","")) -> 0 | J38: =IF(AND('Task list'!$K38>=J$5,'Task list'!$K38<J$5+7),"◆",IF(AND('Task list'!$H38>=J$5,'Task list'!$H38<J$5+7),"◇","")) -> 0 | K38: =IF(AND('Task list'!$K38>=K$5,'Task list'!$K38<K$5+7),"◆",IF(AND('Task list'!$H38>=K$5,'Task list'!$H38<K$5+7),"◇","")) -> 0 | L38: =IF(AND('Task list'!$K38>=L$5,'Task list'!$K38<L$5+7),"◆",IF(AND('Task list'!$H38>=L$5,'Task list'!$H38<L$5+7),"◇","")) -> 0 | M38: =IF(AND('Task list'!$K38>=M$5,'Task list'!$K38<M$5+7),"◆",IF(AND('Task list'!$H38>=M$5,'Task list'!$H38<M$5+7),"◇","")) -> 0 | N38: =IF(AND('Task list'!$K38>=N$5,'Task list'!$K38<N$5+7),"◆",IF(AND('Task list'!$H38>=N$5,'Task list'!$H38<N$5+7),"◇","")) -> 0 | ... V38: =IF(AND('Task list'!$K38>=V$5,'Task list'!$K38<V$5+7),"◆",IF(AND('Task list'!$H38>=V$5,'Task list'!$H38<V$5+7),"◇","")) -> 0 | W38: ='Task list'!G38 -> 2026-05-20 00:00:00 | X38: ='Task list'!H38 -> 2026-05-20 00:00:00 | Y38: ='Task list'!N38 -> Yes
A39: ='Task list'!A39 -> 34 | B39: ='Task list'!B39 -> 7.3 | C39: ='Task list'!C39 -> Hypercare support | D39: ='Task list'!J39 -> 2026-05-28 00:00:00 | E39: ='Task list'!K39 -> 2026-06-10 00:00:00 | F39: ='Task list'!M39 -> 0 | W39: ='Task list'!G39 -> 2026-05-21 00:00:00 | X39: ='Task list'!H39 -> 2026-06-04 00:00:00 | Y39: ='Task list'!N39
A40: ='Task list'!A40 -> 35 | B40: ='Task list'!B40 -> 8 | C40: ='Task list'!C40 -> Closure | D40: ='Task list'!J40 -> 2026-06-11 00:00:00 | E40: ='Task list'!K40 -> 2026-06-16 00:00:00 | F40: ='Task list'!M40 -> 0 | W40: ='Task list'!G40 -> 2026-06-05 00:00:00 | X40: ='Task list'!H40 -> 2026-06-10 00:00:00 | Y40: ='Task list'!N40
A41: ='Task list'!A41 -> 36 | B41: ='Task list'!B41 -> 8.1 | C41: ='Task list'!C41 -> Lessons learned workshop | D41: ='Task list'!J41 -> 2026-06-11 00:00:00 | E41: ='Task list'!K41 -> 2026-06-11 00:00:00 | F41: ='Task list'!M41 -> 0 | W41: ='Task list'!G41 -> 2026-06-05 00:00:00 | X41: ='Task list'!H41 -> 2026-06-05 00:00:00 | Y41: ='Task list'!N41
...

Sheet Milestones
A1: ⚠ SIMULATED PROJECT: FICTIONAL COMPANY, CREATED FOR PORTFOLIO AND LEARNING PURPOSES · Cobbleway Home Services Ltd is not a real business
A2: Milestone plan
A5: WBS | B5: Milestone | C5: Approver | D5: Baseline | E5: Actual | F5: Variance (wd)
A6: 1.4 | B6: M1 Charter and business case approved | C6: Helen Marsh | D6: 46092 | E6: 46092 | F6: =IF(E6>=D6,NETWORKDAYS(D6,E6,Holidays)-1,-(NETWORKDAYS(E6,D6,Holidays)-1)) -> 0
A7: 2.3 | B7: M2 Requirements signed off | C7: Dave Pearson | D7: 46105 | E7: 46105 | F7: =IF(E7>=D7,NETWORKDAYS(D7,E7,Holidays)-1,-(NETWORKDAYS(E7,D7,Holidays)-1)) -> 0
A8: 2.5 | B8: M3 Supplier selected and contract signed | C8: Helen Marsh | D8: 46119 | E8: 46119 | F8: =IF(E8>=D8,NETWORKDAYS(D8,E8,Holidays)-1,-(NETWORKDAYS(E8,D8,Holidays)-1)) -> 0
A9: 3.6 | B9: M4 Configuration complete | C9: Sam Carter | D9: 46154 | E9: 46154 | F9: =IF(E9>=D9,NETWORKDAYS(D9,E9,Holidays)-1,-(NETWORKDAYS(E9,D9,Holidays)-1)) -> 0
A10: 5.3 | B10: M5 Go/no-go decision | C10: Helen Marsh | D10: 46160 | E10: 46164 | F10: =IF(E10>=D10,NETWORKDAYS(D10,E10,Holidays)-1,-(NETWORKDAYS(E10,D10,Holidays)-1)) -> 0
A11: 7.2 | B11: M6 Go-live | C11: Helen Marsh | D11: 46162 | E11: 46169 | F11: =IF(E11>=D11,NETWORKDAYS(D11,E11,Holidays)-1,-(NETWORKDAYS(E11,D11,Holidays)-1)) -> 0
A12: 8.3 | B12: M7 Project closed | C12: Helen Marsh | D12: 46183 | E12: 46189 | F12: =IF(E12>=D12,NETWORKDAYS(D12,E12,Holidays)-1,-(NETWORKDAYS(E12,D12,Holidays)-1)) -> 0

Sheet Holidays
A1: ⚠ SIMULATED PROJECT: FICTIONAL COMPANY, CREATED FOR PORTFOLIO AND LEARNING PURPOSES · Cobbleway Home Services Ltd is not a real business
A2: UK bank holidays in the project window
A3: Used by NETWORKDAYS formulas.
A5: Date | B5: Holiday
A6: 46115 | B6: Good Friday
A7: 46118 | B7: Easter Monday
A8: 46146 | B8: Early May bank holiday
A9: 46167 | B9: Spring bank holiday
