Workbook
Name Holidays: Holidays!$A$6:$A$9
Name StatusDate: Dashboard!$B$4

Sheet Dashboard
A1: ⚠ SIMULATED PROJECT: FICTIONAL COMPANY, CREATED FOR PORTFOLIO AND LEARNING PURPOSES · Cobbleway Home Services Ltd is not a real business
A2: Project Compass: project status dashboard
A3: Cobbleway Home Services Ltd (fictional) · CRM implementation · Highlight report 5 · Project manager: Chidera Ikenna-Obi (simulated role)
A4: Status date (input) | B4: 46150 | C4: Week 10 of 15 | H4: Overall RAG | I4: =IF(COUNTIF(B8:B12,"Red")>0,"Red",IF(COUNTIF(B8:B12,"Amber")>0,"Amber","Green")) -> 0
A6: RAG summary | H6: Key figures
A7: Dimension | B7: RAG | C7: How it is calculated | H7: Total budget (incl. contingency) | J7: Actual spend to date | L7: Forecast at completion
A8: Schedule | B8: =IF(MAX(Milestones!$E$6:$E$12)>5,"Red",IF(MAX(Milestones!$E$6:$E$12)>0,"Amber","Green")) -> 0 | C8: Worst forecast milestone slip: 0 = G, 1–5 wd = A, >5 wd (tolerance) = R | H8: =Budget!B14 -> 0 | J8: =Budget!C12 -> 0 | L8: =Budget!D12 -> 0
A9: Cost | B9: =IF(Budget!D12>Budget!B14,"Red",IF(Budget!D12>Budget!B12,"Amber","Green")) -> 0 | C9: EAC ≤ base = G; within contingency = A; above total budget = R
A10: Scope | B10: ="Green" -> 0 | C10: Manual: all Must requirements in plan; CR01 approved | H10: Contingency remaining | J10: Milestones achieved | L10: Open risks
A11: Risks | B11: =IF(SUMPRODUCT((Risks!$F$6:$F$14>=15)*(Risks!$C$6:$C$14<=StatusDate)*((Risks!$G$6:$G$14="")+(Risks!$G$6:$G$14>StatusDate)))>1,"Red",IF(SUMPRODUCT((Risks!$F$6:$F$14>=15)*(Risks!$C$6:$C$14<=StatusDate)*((Risks!$G$6:$G$14="")+(Risks!$G$6:$G$14>StatusDate)))=1,"Amber","Green")) -> 0 | C11: Open risks scoring 15+: 0 = G, 1 = A, 2+ = R | H11: =Budget!B15 -> 0 | J11: =COUNTIF(Milestones!$D$6:$D$12,"<="&StatusDate)/7 -> 0 | L11: =SUMPRODUCT((Risks!$C$6:$C$14<=StatusDate)*((Risks!$G$6:$G$14="")+(Risks!$G$6:$G$14>StatusDate))) -> 0
A12: Issues | B12: =IF(SUMPRODUCT((Issues!$D$6:$D$9="High")*(Issues!$C$6:$C$9<=StatusDate)*((Issues!$E$6:$E$9="")+(Issues!$E$6:$E$9>StatusDate)))>0,"Amber","Green") -> 0 | C12: Any open High issue = A
A14: Milestone tracker | H14: Risk heatmap (open risks at status date)
A15: Milestone | B15: Baseline | C15: Forecast / actual | D15: Variance (wd) | E15: Status | F15: RAG | H15: Probability ↓ Impact → | I15: 1 | J15: 2 | K15: 3 | L15: 4 | M15: 5
A16: =Milestones!B6 -> 0 | B16: =Milestones!C6 -> 0 | C16: =Milestones!D6 -> 0 | D16: =Milestones!E6 -> 0 | E16: =IF(C16<=StatusDate,"Achieved",IF(D16>0,"Forecast late","On track")) -> 0 | F16: =IF(D16>5,"Red",IF(D16>0,"Amber","Green")) -> 0 | H16: 5 | I16: =COUNTIFS(Risks!$D$6:$D$14,5,Risks!$E$6:$E$14,1,Risks!$C$6:$C$14,"<="&StatusDate,Risks!$G$6:$G$14,">"&StatusDate)+COUNTIFS(Risks!$D$6:$D$14,5,Risks!$E$6:$E$14,1,Risks!$C$6:$C$14,"<="&StatusDate,Risks!$G$6:$G$14,"") -> 0 | J16: =COUNTIFS(Risks!$D$6:$D$14,5,Risks!$E$6:$E$14,2,Risks!$C$6:$C$14,"<="&StatusDate,Risks!$G$6:$G$14,">"&StatusDate)+COUNTIFS(Risks!$D$6:$D$14,5,Risks!$E$6:$E$14,2,Risks!$C$6:$C$14,"<="&StatusDate,Risks!$G$6:$G$14,"") -> 0 | K16: =COUNTIFS(Risks!$D$6:$D$14,5,Risks!$E$6:$E$14,3,Risks!$C$6:$C$14,"<="&StatusDate,Risks!$G$6:$G$14,">"&StatusDate)+COUNTIFS(Risks!$D$6:$D$14,5,Risks!$E$6:$E$14,3,Risks!$C$6:$C$14,"<="&StatusDate,Risks!$G$6:$G$14,"") -> 0 | L16: =COUNTIFS(Risks!$D$6:$D$14,5,Risks!$E$6:$E$14,4,Risks!$C$6:$C$14,"<="&StatusDate,Risks!$G$6:$G$14,">"&StatusDate)+COUNTIFS(Risks!$D$6:$D$14,5,Risks!$E$6:$E$14,4,Risks!$C$6:$C$14,"<="&StatusDate,Risks!$G$6:$G$14,"") -> 0 | M16: =COUNTIFS(Risks!$D$6:$D$14,5,Risks!$E$6:$E$14,5,Risks!$C$6:$C$14,"<="&StatusDate,Risks!$G$6:$G$14,">"&StatusDate)+COUNTIFS(Risks!$D$6:$D$14,5,Risks!$E$6:$E$14,5,Risks!$C$6:$C$14,"<="&StatusDate,Risks!$G$6:$G$14,"") -> 0
A17: =Milestones!B7 -> 0 | B17: =Milestones!C7 -> 0 | C17: =Milestones!D7 -> 0 | D17: =Milestones!E7 -> 0 | E17: =IF(C17<=StatusDate,"Achieved",IF(D17>0,"Forecast late","On track")) -> 0 | F17: =IF(D17>5,"Red",IF(D17>0,"Amber","Green")) -> 0 | H17: 4 | I17: =COUNTIFS(Risks!$D$6:$D$14,4,Risks!$E$6:$E$14,1,Risks!$C$6:$C$14,"<="&StatusDate,Risks!$G$6:$G$14,">"&StatusDate)+COUNTIFS(Risks!$D$6:$D$14,4,Risks!$E$6:$E$14,1,Risks!$C$6:$C$14,"<="&StatusDate,Risks!$G$6:$G$14,"") -> 0 | J17: =COUNTIFS(Risks!$D$6:$D$14,4,Risks!$E$6:$E$14,2,Risks!$C$6:$C$14,"<="&StatusDate,Risks!$G$6:$G$14,">"&StatusDate)+COUNTIFS(Risks!$D$6:$D$14,4,Risks!$E$6:$E$14,2,Risks!$C$6:$C$14,"<="&StatusDate,Risks!$G$6:$G$14,"") -> 0 | K17: =COUNTIFS(Risks!$D$6:$D$14,4,Risks!$E$6:$E$14,3,Risks!$C$6:$C$14,"<="&StatusDate,Risks!$G$6:$G$14,">"&StatusDate)+COUNTIFS(Risks!$D$6:$D$14,4,Risks!$E$6:$E$14,3,Risks!$C$6:$C$14,"<="&StatusDate,Risks!$G$6:$G$14,"") -> 0 | L17: =COUNTIFS(Risks!$D$6:$D$14,4,Risks!$E$6:$E$14,4,Risks!$C$6:$C$14,"<="&StatusDate,Risks!$G$6:$G$14,">"&StatusDate)+COUNTIFS(Risks!$D$6:$D$14,4,Risks!$E$6:$E$14,4,Risks!$C$6:$C$14,"<="&StatusDate,Risks!$G$6:$G$14,"") -> 0 | M17: =COUNTIFS(Risks!$D$6:$D$14,4,Risks!$E$6:$E$14,5,Risks!$C$6:$C$14,"<="&StatusDate,Risks!$G$6:$G$14,">"&StatusDate)+COUNTIFS(Risks!$D$6:$D$14,4,Risks!$E$6:$E$14,5,Risks!$C$6:$C$14,"<="&StatusDate,Risks!$G$6:$G$14,"") -> 0
A18: =Milestones!B8 -> 0 | B18: =Milestones!C8 -> 0 | C18: =Milestones!D8 -> 0 | D18: =Milestones!E8 -> 0 | E18: =IF(C18<=StatusDate,"Achieved",IF(D18>0,"Forecast late","On track")) -> 0 | F18: =IF(D18>5,"Red",IF(D18>0,"Amber","Green")) -> 0 | H18: 3 | I18: =COUNTIFS(Risks!$D$6:$D$14,3,Risks!$E$6:$E$14,1,Risks!$C$6:$C$14,"<="&StatusDate,Risks!$G$6:$G$14,">"&StatusDate)+COUNTIFS(Risks!$D$6:$D$14,3,Risks!$E$6:$E$14,1,Risks!$C$6:$C$14,"<="&StatusDate,Risks!$G$6:$G$14,"") -> 0 | J18: =COUNTIFS(Risks!$D$6:$D$14,3,Risks!$E$6:$E$14,2,Risks!$C$6:$C$14,"<="&StatusDate,Risks!$G$6:$G$14,">"&StatusDate)+COUNTIFS(Risks!$D$6:$D$14,3,Risks!$E$6:$E$14,2,Risks!$C$6:$C$14,"<="&StatusDate,Risks!$G$6:$G$14,"") -> 0 | K18: =COUNTIFS(Risks!$D$6:$D$14,3,Risks!$E$6:$E$14,3,Risks!$C$6:$C$14,"<="&StatusDate,Risks!$G$6:$G$14,">"&StatusDate)+COUNTIFS(Risks!$D$6:$D$14,3,Risks!$E$6:$E$14,3,Risks!$C$6:$C$14,"<="&StatusDate,Risks!$G$6:$G$14,"") -> 0 | L18: =COUNTIFS(Risks!$D$6:$D$14,3,Risks!$E$6:$E$14,4,Risks!$C$6:$C$14,"<="&StatusDate,Risks!$G$6:$G$14,">"&StatusDate)+COUNTIFS(Risks!$D$6:$D$14,3,Risks!$E$6:$E$14,4,Risks!$C$6:$C$14,"<="&StatusDate,Risks!$G$6:$G$14,"") -> 0 | M18: =COUNTIFS(Risks!$D$6:$D$14,3,Risks!$E$6:$E$14,5,Risks!$C$6:$C$14,"<="&StatusDate,Risks!$G$6:$G$14,">"&StatusDate)+COUNTIFS(Risks!$D$6:$D$14,3,Risks!$E$6:$E$14,5,Risks!$C$6:$C$14,"<="&StatusDate,Risks!$G$6:$G$14,"") -> 0
A19: =Milestones!B9 -> 0 | B19: =Milestones!C9 -> 0 | C19: =Milestones!D9 -> 0 | D19: =Milestones!E9 -> 0 | E19: =IF(C19<=StatusDate,"Achieved",IF(D19>0,"Forecast late","On track")) -> 0 | F19: =IF(D19>5,"Red",IF(D19>0,"Amber","Green")) -> 0 | H19: 2 | I19: =COUNTIFS(Risks!$D$6:$D$14,2,Risks!$E$6:$E$14,1,Risks!$C$6:$C$14,"<="&StatusDate,Risks!$G$6:$G$14,">"&StatusDate)+COUNTIFS(Risks!$D$6:$D$14,2,Risks!$E$6:$E$14,1,Risks!$C$6:$C$14,"<="&StatusDate,Risks!$G$6:$G$14,"") -> 0 | J19: =COUNTIFS(Risks!$D$6:$D$14,2,Risks!$E$6:$E$14,2,Risks!$C$6:$C$14,"<="&StatusDate,Risks!$G$6:$G$14,">"&StatusDate)+COUNTIFS(Risks!$D$6:$D$14,2,Risks!$E$6:$E$14,2,Risks!$C$6:$C$14,"<="&StatusDate,Risks!$G$6:$G$14,"") -> 0 | K19: =COUNTIFS(Risks!$D$6:$D$14,2,Risks!$E$6:$E$14,3,Risks!$C$6:$C$14,"<="&StatusDate,Risks!$G$6:$G$14,">"&StatusDate)+COUNTIFS(Risks!$D$6:$D$14,2,Risks!$E$6:$E$14,3,Risks!$C$6:$C$14,"<="&StatusDate,Risks!$G$6:$G$14,"") -> 0 | L19: =COUNTIFS(Risks!$D$6:$D$14,2,Risks!$E$6:$E$14,4,Risks!$C$6:$C$14,"<="&StatusDate,Risks!$G$6:$G$14,">"&StatusDate)+COUNTIFS(Risks!$D$6:$D$14,2,Risks!$E$6:$E$14,4,Risks!$C$6:$C$14,"<="&StatusDate,Risks!$G$6:$G$14,"") -> 0 | M19: =COUNTIFS(Risks!$D$6:$D$14,2,Risks!$E$6:$E$14,5,Risks!$C$6:$C$14,"<="&StatusDate,Risks!$G$6:$G$14,">"&StatusDate)+COUNTIFS(Risks!$D$6:$D$14,2,Risks!$E$6:$E$14,5,Risks!$C$6:$C$14,"<="&StatusDate,Risks!$G$6:$G$14,"") -> 0
A20: =Milestones!B10 -> 0 | B20: =Milestones!C10 -> 0 | C20: =Milestones!D10 -> 0 | D20: =Milestones!E10 -> 0 | E20: =IF(C20<=StatusDate,"Achieved",IF(D20>0,"Forecast late","On track")) -> 0 | F20: =IF(D20>5,"Red",IF(D20>0,"Amber","Green")) -> 0 | H20: 1 | I20: =COUNTIFS(Risks!$D$6:$D$14,1,Risks!$E$6:$E$14,1,Risks!$C$6:$C$14,"<="&StatusDate,Risks!$G$6:$G$14,">"&StatusDate)+COUNTIFS(Risks!$D$6:$D$14,1,Risks!$E$6:$E$14,1,Risks!$C$6:$C$14,"<="&StatusDate,Risks!$G$6:$G$14,"") -> 0 | J20: =COUNTIFS(Risks!$D$6:$D$14,1,Risks!$E$6:$E$14,2,Risks!$C$6:$C$14,"<="&StatusDate,Risks!$G$6:$G$14,">"&StatusDate)+COUNTIFS(Risks!$D$6:$D$14,1,Risks!$E$6:$E$14,2,Risks!$C$6:$C$14,"<="&StatusDate,Risks!$G$6:$G$14,"") -> 0 | K20: =COUNTIFS(Risks!$D$6:$D$14,1,Risks!$E$6:$E$14,3,Risks!$C$6:$C$14,"<="&StatusDate,Risks!$G$6:$G$14,">"&StatusDate)+COUNTIFS(Risks!$D$6:$D$14,1,Risks!$E$6:$E$14,3,Risks!$C$6:$C$14,"<="&StatusDate,Risks!$G$6:$G$14,"") -> 0 | L20: =COUNTIFS(Risks!$D$6:$D$14,1,Risks!$E$6:$E$14,4,Risks!$C$6:$C$14,"<="&StatusDate,Risks!$G$6:$G$14,">"&StatusDate)+COUNTIFS(Risks!$D$6:$D$14,1,Risks!$E$6:$E$14,4,Risks!$C$6:$C$14,"<="&StatusDate,Risks!$G$6:$G$14,"") -> 0 | M20: =COUNTIFS(Risks!$D$6:$D$14,1,Risks!$E$6:$E$14,5,Risks!$C$6:$C$14,"<="&StatusDate,Risks!$G$6:$G$14,">"&StatusDate)+COUNTIFS(Risks!$D$6:$D$14,1,Risks!$E$6:$E$14,5,Risks!$C$6:$C$14,"<="&StatusDate,Risks!$G$6:$G$14,"") -> 0
A21: =Milestones!B11 -> 0 | B21: =Milestones!C11 -> 0 | C21: =Milestones!D11 -> 0 | D21: =Milestones!E11 -> 0 | E21: =IF(C21<=StatusDate,"Achieved",IF(D21>0,"Forecast late","On track")) -> 0 | F21: =IF(D21>5,"Red",IF(D21>0,"Amber","Green")) -> 0 | H21: Numbers = count of open risks in each cell. Source: Risks sheet (from the RAID log).
A22: =Milestones!B12 -> 0 | B22: =Milestones!C12 -> 0 | C22: =Milestones!D12 -> 0 | D22: =Milestones!E12 -> 0 | E22: =IF(C22<=StatusDate,"Achieved",IF(D22>0,"Forecast late","On track")) -> 0 | F22: =IF(D22>5,"Red",IF(D22>0,"Amber","Green")) -> 0
A25: Budget vs actual (GBP)
A26: Category | B26: Budget | C26: Actual to date | D26: Forecast (EAC) | E26: Variance | F26: % spent
A27: =Budget!A6 -> 0 | B27: =Budget!B6 -> 0 | C27: =Budget!C6 -> 0 | D27: =Budget!D6 -> 0 | E27: =Budget!E6 -> 0 | F27: =Budget!F6 -> 0
A28: =Budget!A7 -> 0 | B28: =Budget!B7 -> 0 | C28: =Budget!C7 -> 0 | D28: =Budget!D7 -> 0 | E28: =Budget!E7 -> 0 | F28: =Budget!F7 -> 0
A29: =Budget!A8 -> 0 | B29: =Budget!B8 -> 0 | C29: =Budget!C8 -> 0 | D29: =Budget!D8 -> 0 | E29: =Budget!E8 -> 0 | F29: =Budget!F8 -> 0
A30: =Budget!A9 -> 0 | B30: =Budget!B9 -> 0 | C30: =Budget!C9 -> 0 | D30: =Budget!D9 -> 0 | E30: =Budget!E9 -> 0 | F30: =Budget!F9 -> 0
A31: =Budget!A10 -> 0 | B31: =Budget!B10 -> 0 | C31: =Budget!C10 -> 0 | D31: =Budget!D10 -> 0 | E31: =Budget!E10 -> 0 | F31: =Budget!F10 -> 0
A32: =Budget!A11 -> 0 | B32: =Budget!B11 -> 0 | C32: =Budget!C11 -> 0 | D32: =Budget!D11 -> 0 | E32: =Budget!E11 -> 0 | F32: =Budget!F11 -> 0
A33: =Budget!A12 -> 0 | B33: =Budget!B12 -> 0 | C33: =Budget!C12 -> 0 | D33: =Budget!D12 -> 0 | E33: =Budget!E12 -> 0 | F33: =Budget!F12 -> 0
A35: PM commentary (status date)
A36: Amber overall. Data cleansing (task 4.1) is forecast to finish 10 working days late because ~18% of legacy records are duplicates (issue I01). Go-live is forecast for 27 May against a 20 May baseline: a 4 working-day slip, inside the 1-week tolerance. CR01 (accounting connector, £900) approved. EAC is £1,780 over base budget and within contingency. Decision needed: none. Next: complete cleansing, trial migration, UAT from 19 May.
A40: Issues at status date
A41: Issue | B41: ID | C41: Severity | D41: Raised | E41: At status date
A42: =Issues!B6 -> 0 | B42: =Issues!A6 -> 0 | C42: =Issues!D6 -> 0 | D42: =Issues!C6 -> 0 | E42: =IF(Issues!C6>StatusDate,"Not yet raised",IF(OR(Issues!E6="",Issues!E6>StatusDate),"Open","Closed")) -> 0
A43: =Issues!B7 -> 0 | B43: =Issues!A7 -> 0 | C43: =Issues!D7 -> 0 | D43: =Issues!C7 -> 0 | E43: =IF(Issues!C7>StatusDate,"Not yet raised",IF(OR(Issues!E7="",Issues!E7>StatusDate),"Open","Closed")) -> 0
A44: =Issues!B8 -> 0 | B44: =Issues!A8 -> 0 | C44: =Issues!D8 -> 0 | D44: =Issues!C8 -> 0 | E44: =IF(Issues!C8>StatusDate,"Not yet raised",IF(OR(Issues!E8="",Issues!E8>StatusDate),"Open","Closed")) -> 0
A45: =Issues!B9 -> 0 | B45: =Issues!A9 -> 0 | C45: =Issues!D9 -> 0 | D45: =Issues!C9 -> 0 | E45: =IF(Issues!C9>StatusDate,"Not yet raised",IF(OR(Issues!E9="",Issues!E9>StatusDate),"Open","Closed")) -> 0
A47: Next fortnight
A48: • Finish data cleansing (4.1) and run trial migration with reconciliation (4.2)
A49: • Complete configuration (M4, 12 May); tablets enrolled and tested offline
...

Sheet Milestones
A1: ⚠ SIMULATED PROJECT: FICTIONAL COMPANY, CREATED FOR PORTFOLIO AND LEARNING PURPOSES · Cobbleway Home Services Ltd is not a real business
A2: Milestone data
A3: Forecast = latest forecast at the status date (actual if achieved).
A5: WBS | B5: Milestone | C5: Baseline | D5: Forecast / actual | E5: Variance (wd)
A6: 1.4 | B6: M1 Charter and business case approved | C6: 46092 | D6: 46092 | E6: =IF(D6>=C6,NETWORKDAYS(C6,D6,Holidays)-1,-(NETWORKDAYS(D6,C6,Holidays)-1)) -> 0
A7: 2.3 | B7: M2 Requirements signed off | C7: 46105 | D7: 46105 | E7: =IF(D7>=C7,NETWORKDAYS(C7,D7,Holidays)-1,-(NETWORKDAYS(D7,C7,Holidays)-1)) -> 0
A8: 2.5 | B8: M3 Supplier selected and contract signed | C8: 46119 | D8: 46119 | E8: =IF(D8>=C8,NETWORKDAYS(C8,D8,Holidays)-1,-(NETWORKDAYS(D8,C8,Holidays)-1)) -> 0
A9: 3.6 | B9: M4 Configuration complete | C9: 46154 | D9: 46154 | E9: =IF(D9>=C9,NETWORKDAYS(C9,D9,Holidays)-1,-(NETWORKDAYS(D9,C9,Holidays)-1)) -> 0
A10: 5.3 | B10: M5 Go/no-go decision | C10: 46160 | D10: 46164 | E10: =IF(D10>=C10,NETWORKDAYS(C10,D10,Holidays)-1,-(NETWORKDAYS(D10,C10,Holidays)-1)) -> 0
A11: 7.2 | B11: M6 Go-live | C11: 46162 | D11: 46169 | E11: =IF(D11>=C11,NETWORKDAYS(C11,D11,Holidays)-1,-(NETWORKDAYS(D11,C11,Holidays)-1)) -> 0
A12: 8.3 | B12: M7 Project closed | C12: 46183 | D12: 46189 | E12: =IF(D12>=C12,NETWORKDAYS(C12,D12,Holidays)-1,-(NETWORKDAYS(D12,C12,Holidays)-1)) -> 0

Sheet Budget
A1: ⚠ SIMULATED PROJECT: FICTIONAL COMPANY, CREATED FOR PORTFOLIO AND LEARNING PURPOSES · Cobbleway Home Services Ltd is not a real business
A2: Budget vs actual (GBP)
A3: Actual to date at status date 08 May 2026. EAC = estimate at completion.
A5: Category | B5: Budget | C5: Actual to date | D5: Forecast (EAC) | E5: Variance (EAC − budget) | F5: % spent
A6: CRM licences (18 users, year 1) | B6: 6800 | C6: 6800 | D6: 6800 | E6: =D6-B6 -> 0 | F6: =IF(B6=0,0,C6/B6) -> 0
A7: Supplier configuration and integration | B7: 9500 | C7: 7600 | D7: 10400 | E7: =D7-B7 -> 0 | F7: =IF(B7=0,0,C7/B7) -> 0
A8: Data migration and cleansing | B8: 4200 | C8: 4200 | D8: 4900 | E8: =D8-B8 -> 0 | F8: =IF(B8=0,0,C8/B8) -> 0
A9: Training and materials | B9: 3000 | C9: 600 | D9: 3000 | E9: =D9-B9 -> 0 | F9: =IF(B9=0,0,C9/B9) -> 0
A10: Internal staff time (backfill) | B10: 6000 | C10: 3900 | D10: 6300 | E10: =D10-B10 -> 0 | F10: =IF(B10=0,0,C10/B10) -> 0
A11: Hardware (6 rugged tablets and cases) | B11: 3500 | C11: 3380 | D11: 3380 | E11: =D11-B11 -> 0 | F11: =IF(B11=0,0,C11/B11) -> 0
A12: Base budget total | B12: =SUM(B6:B11) -> 0 | C12: =SUM(C6:C11) -> 0 | D12: =SUM(D6:D11) -> 0 | E12: =SUM(E6:E11) -> 0 | F12: =C12/B12 -> 0
A13: Contingency (10.6% of base) | B13: 3500
A14: Total approved budget (incl. contingency) | B14: =B12+B13 -> 0
A15: Contingency remaining at EAC | B15: =B14-D12 -> 0

Sheet Spend profile
A1: ⚠ SIMULATED PROJECT: FICTIONAL COMPANY, CREATED FOR PORTFOLIO AND LEARNING PURPOSES · Cobbleway Home Services Ltd is not a real business
A2: Cumulative spend profile (GBP)
A3: Actual for May is to the status date only.
A5: Month | B5: Planned (cumulative) | C5: Actual (cumulative)
A6: Mar 2026 | B6: 2100 | C6: 2050
A7: Apr 2026 | B7: 17400 | C7: 18350
A8: May 2026 | B8: 28900 | C8: 26480
A9: Jun 2026 | B9: 33000

Sheet Risks
A1: ⚠ SIMULATED PROJECT: FICTIONAL COMPANY, CREATED FOR PORTFOLIO AND LEARNING PURPOSES · Cobbleway Home Services Ltd is not a real business
A2: Risk data (copy of RAID log risks)
A3: Heatmap counts risks open at the status date: raised on or before it and not closed by then.
A5: ID | B5: Risk | C5: Raised | D5: Prob. | E5: Impact | F5: Score | G5: Closed
A6: R01 | B6: Poor legacy data quality delays migration | C6: 46090 | D6: 4 | E6: 4 | F6: =D6*E6 -> 0 | G6: 46160
A7: R02 | B7: Field engineers do not adopt the mobile app | C7: 46090 | D7: 3 | E7: 4 | F7: =D7*E7 -> 0
A8: R03 | B8: Accounting integration more complex than quoted | C8: 46104 | D8: 3 | E8: 4 | F8: =D8*E8 -> 0 | G8: 46139
A9: R04 | B9: Key staff unavailable for UAT and training | C9: 46097 | D9: 3 | E9: 3 | F9: =D9*E9 -> 0 | G9: 46157
A10: R05 | B10: Supplier resourcing slips configuration | C10: 46114 | D10: 2 | E10: 4 | F10: =D10*E10 -> 0 | G10: 46154
A11: R06 | B11: Customer data migrated without proper retention review | C11: 46097 | D11: 2 | E11: 5 | F11: =D11*E11 -> 0 | G11: 46169
A12: R07 | B12: Change requests push cost over tolerance | C12: 46125 | D12: 3 | E12: 3 | F12: =D12*E12 -> 0 | G12: 46189
A13: R08 | B13: Low mobile signal stops job updates | C13: 46104 | D13: 3 | E13: 2 | F13: =D13*E13 -> 0 | G13: 46157
A14: R09 | B14: Go-live disrupts customer service | C14: 46132 | D14: 2 | E14: 4 | F14: =D14*E14 -> 0 | G14: 46183

Sheet Issues
A1: ⚠ SIMULATED PROJECT: FICTIONAL COMPANY, CREATED FOR PORTFOLIO AND LEARNING PURPOSES · Cobbleway Home Services Ltd is not a real business
A2: Issue data (copy of RAID log issues)
A5: ID | B5: Issue | C5: Raised | D5: Severity | E5: Closed
A6: I01 | B6: Around 18% of legacy customer records are duplicates | C6: 46133 | D6: High | E6: 46155
A7: I02 | B7: Accounting package needs a paid connector for invoice sync | C7: 46128 | D7: Medium | E7: 46139
A8: I03 | B8: Two tablets faulty on delivery | C8: 46148 | D8: Low | E8: 46154
A9: I04 | B9: UAT: VAT rounding error on quote PDF template | C9: 46162 | D9: Medium | E9: 46164

Sheet Holidays
A1: ⚠ SIMULATED PROJECT: FICTIONAL COMPANY, CREATED FOR PORTFOLIO AND LEARNING PURPOSES · Cobbleway Home Services Ltd is not a real business
A2: UK bank holidays
A5: Date | B5: Holiday
A6: 46115 | B6: Good Friday
A7: 46118 | B7: Easter Monday
A8: 46146 | B8: Early May bank holiday
A9: 46167 | B9: Spring bank holiday
